<?xml version='1.0'?>
 
<robot name="robot" 
  xmlns:xacro="http://www.ros.org/wiki/xacro">
 
  <xacro:include filename="robot.gazebo" />

  <!-- base_footprint -->

  <link name="robot_footprint"></link>
 
  <joint name="robot_footprint_joint" type="fixed">
    <origin xyz="0 0 0" rpy="0 0 0" />
    <parent link="robot_footprint"/>
    <child link="base_link" />
  </joint>


  <!-- base_link -->

  <link name='base_link'>
    <pose>0 0 0.1 0 0 0</pose>
 
    <inertial>
      <mass value="15.0"/>
      <origin xyz="0.0 0 0" rpy=" 0 0 0"/>
      <inertia ixx="0.1" ixy="0" ixz="0" iyy="0.1" iyz="0" izz="0.1" />
    </inertial>
 
    <collision name='collision'>
      <origin xyz="0 0 0" rpy=" 0 0 0"/>
      <geometry>
        <box size=".4 .2 .1"/>
      </geometry>
    </collision>
 
    <visual name='base_link_visual'>
      <origin xyz="0 0 0" rpy=" 0 0 0"/>
      <geometry>
        <box size=".4 .2 .1"/>
      </geometry>
    </visual>
  </link>

  <gazebo reference="base_link">
    <material>Gazebo/Blue</material>
  </gazebo>


  <!-- front_left_wheel -->

  <link name="front_left_wheel">
    <inertial>
      <mass value="5.0"/>
      <origin xyz="0.0 0 0" rpy=" 0 1.5707 1.5707"/>
      <inertia ixx="0.1" ixy="0" ixz="0" iyy="0.1" iyz="0" izz="0.1" />
    </inertial>
 
    <visual>
      <origin xyz="0.0 0 0" rpy=" 0 1.5707 1.5707"/>
      <geometry>
        <cylinder length="0.05" radius="0.06"/>
      </geometry>
    </visual>
 
    <collision>
      <origin xyz="0.0 0 0" rpy=" 0 1.5707 1.5707"/>
      <geometry>
        <cylinder length="0.05" radius="0.06"/>
      </geometry>
    </collision>
  </link>

  <joint type="continuous" name="front_left_wheel_joint">
    <origin xyz="0.12 0.15 0" rpy="0 0 0"/>
    <child link="front_left_wheel"/>
    <parent link="base_link"/>
    <axis xyz="0 1 0" rpy="0 0 0"/>
    <limit effort="10000" velocity="1000"/>
    <dynamics damping="1.0" friction="1.0"/>
  </joint>

  <gazebo reference="front_left_wheel">
    <material>Gazebo/Gray</material>
  </gazebo>
 

  <!-- back_left_wheel -->

  <link name="back_left_wheel">
    <inertial>
      <mass value="5.0"/>
      <origin xyz="0.0 0 0" rpy=" 0 1.5707 1.5707"/>
      <inertia ixx="0.1" ixy="0" ixz="0" iyy="0.1" iyz="0" izz="0.1" />
    </inertial>
 
    <visual>
      <origin xyz="0.0 0 0" rpy=" 0 1.5707 1.5707"/>
      <geometry>
        <cylinder length="0.05" radius="0.06"/>
      </geometry>
    </visual>
 
    <collision>
      <origin xyz="0.0 0 0" rpy=" 0 1.5707 1.5707"/>
      <geometry>
        <cylinder length="0.05" radius="0.06"/>
      </geometry>
    </collision>
  </link>

  <joint type="continuous" name="back_left_wheel_joint">
    <origin xyz="-0.12 0.15 0" rpy="0 0 0"/>
    <child link="back_left_wheel"/>
    <parent link="base_link"/>
    <axis xyz="0 1 0" rpy="0 0 0"/>
    <limit effort="10000" velocity="1000"/>
    <dynamics damping="1.0" friction="1.0"/>
  </joint>

  <gazebo reference="back_left_wheel">
    <material>Gazebo/Gray</material>
  </gazebo>
 

  <!-- front_right_wheel -->

  <link name="front_right_wheel">
    <inertial>
      <mass value="5.0"/>
      <origin xyz="0.0 0 0" rpy=" 0 1.5707 1.5707"/>
      <inertia ixx="0.1" ixy="0" ixz="0" iyy="0.1" iyz="0" izz="0.1" />
    </inertial>
 
    <visual>
      <origin xyz="0.0 0 0" rpy=" 0 1.5707 1.5707"/>
      <geometry>
        <cylinder length="0.05" radius="0.06"/>
      </geometry>
    </visual>
 
    <collision>
      <origin xyz="0.0 0 0" rpy=" 0 1.5707 1.5707"/>
      <geometry>
        <cylinder length="0.05" radius="0.06"/>
      </geometry>
    </collision>
  </link>

  <joint type="continuous" name="front_right_wheel_joint">
    <origin xyz="0.12 -0.15 0" rpy="0 0 0"/>
    <child link="front_right_wheel"/>
    <parent link="base_link"/>
    <axis xyz="0 1 0" rpy="0 0 0"/>
    <limit effort="10000" velocity="1000"/>
    <dynamics damping="1.0" friction="1.0"/>
  </joint>
 
  <gazebo reference="front_right_wheel">
    <material>Gazebo/Gray</material>
  </gazebo>


  <!-- back_right_wheel -->

  <link name="back_right_wheel">
    <inertial>
      <mass value="5.0"/>
      <origin xyz="0.0 0 0" rpy=" 0 1.5707 1.5707"/>
      <inertia ixx="0.1" ixy="0" ixz="0" iyy="0.1" iyz="0" izz="0.1" />
    </inertial>
 
    <visual>
      <origin xyz="0.0 0 0" rpy=" 0 1.5707 1.5707"/>
      <geometry>
        <cylinder length="0.05" radius="0.06"/>
      </geometry>
    </visual>
 
    <collision>
      <origin xyz="0.0 0 0" rpy=" 0 1.5707 1.5707"/>
      <geometry>
        <cylinder length="0.05" radius="0.06"/>
      </geometry>
    </collision>
  </link>

  <joint type="continuous" name="back_right_wheel_joint">
    <origin xyz="-0.12 -0.15 0" rpy="0 0 0"/>
    <child link="back_right_wheel"/>
    <parent link="base_link"/>
    <axis xyz="0 1 0" rpy="0 0 0"/>
    <limit effort="10000" velocity="1000"/>
    <dynamics damping="1.0" friction="1.0"/>
  </joint>
   
  <gazebo reference="back_right_wheel">
    <material>Gazebo/Gray</material>
  </gazebo>
 
 
  <!-- camera -->

  <link name="camera">
    <inertial>
      <mass value="0.1"/>
      <origin xyz="0.05 0.05 0.05" rpy=" 0 0 0"/>
      <inertia ixx="1e-6" ixy="0" ixz="0" iyy="1e-6" iyz="0" izz="1e-6" />
    </inertial>
 
    <visual name="camera_visual">
      <origin xyz="0 0 0" rpy="0 0 0" />
      <geometry>
        <box size="0.05 0.05 0.05"/>
      </geometry>
    </visual>
 
    <collision name="camera_colision">
      <origin xyz="0 0 0" rpy="0 0 0" />
      <geometry>
        <box size="0.05 0.05 0.05"/>
      </geometry>
    </collision>
  </link>

  <joint type="fixed" name="camera_joint">
    <origin xyz="0.2 0 0" rpy="0 0 0"/>
    <child link="camera"/>
    <parent link="base_link"/>
    <axis xyz="0 1 0" rpy="0 0 0"/>
  </joint>

  <gazebo reference="camera">
    <material>Gazebo/Red</material>
  </gazebo>
 

  <!-- lidar -->

  <link name="lidar">
    <inertial>
      <mass value="1e-5"/>
      <origin xyz="0 0 0" rpy=" 0 0 0"/>
      <inertia ixx="1e-6" ixy="0" ixz="0" iyy="1e-6" iyz="0" izz="1e-6" />
    </inertial>
 
    <visual name="lidar_visual">
      <origin xyz="0 0 0" rpy="0 0 0" />
      <geometry>
        <!-- <mesh filename="$(find robot)/meshes/lidar.dae"/> -->
        <box size="0.05 0.05 0.05"/>
      </geometry>
    </visual>
 
    <collision name="lidar_colision">
      <origin xyz="0 0 0" rpy="0 0 0" />
      <geometry>
        <box size="0.1 0.1 0.1"/>
      </geometry>
    </collision>
  </link>

  <joint type="fixed" name="lidar_joint">
    <origin xyz="0.15 0 0.1" rpy="0 0 0"/>
    <child link="lidar"/>
    <parent link="base_link"/>
    <axis xyz="0 1 0" rpy="0 0 0"/>
  </joint>

  <gazebo reference="lidar">
    <material>Gazebo/Black</material>
  </gazebo>
 
</robot>
